<?xml version='1.0' encoding='utf-8'?>
<robot name="Robot_sacara_examen">
    <link name="base_link">
        <inertial>
            <origin xyz="4.467610416760825e-18 4.467610416760825e-18 0.023333333333333334" rpy="0.0 0.0 0.0" />
            <mass value="0.15115458893481928" />
            <inertia ixx="6.308604718737988e-05" iyy="6.30860471873781e-05" izz="6.235126793561208e-05" ixy="3.016976492694914e-36" iyz="2.250999386887998e-21" ixz="2.250999386887998e-21" />
        </inertial>
        <visual name="base_link_visual">
            <origin xyz="0.0 0.0 0.0" rpy="0.0 0.0 0.0" />
            <geometry>
                <mesh filename="package://robot_4r_description/meshes/base_link.stl" scale="0.001 0.001 0.001" />
            </geometry>
        </visual>
        <collision name="base_link_collision">
            <origin xyz="0.0 0.0 0.0" rpy="0.0 0.0 0.0" />
            <geometry>
                <mesh filename="package://robot_4r_description/meshes/base_link.stl" scale="0.001 0.001 0.001" />
            </geometry>
        </collision>
    </link>
    <link name="link_1">
        <inertial>
            <origin xyz="0.06736368973851624 0.0 0.015701303784620597" rpy="0.0 -0.0 0.0" />
            <mass value="0.26609096901450546" />
            <inertia ixx="7.843395075980036e-05" iyy="0.0005532669420485318" izz="0.0005833404940655486" ixy="0.0" iyz="1.3505996321327985e-20" ixz="-9.822493630395066e-06" />
        </inertial>
        <visual name="link_1_visual">
            <origin xyz="0.0 0.0 -0.04" rpy="0.0 -0.0 0.0" />
            <geometry>
                <mesh filename="package://robot_4r_description/meshes/link_1.stl" scale="0.001 0.001 0.001" />
            </geometry>
        </visual>
        <collision name="link_1_collision">
            <origin xyz="0.0 0.0 -0.04" rpy="0.0 -0.0 0.0" />
            <geometry>
                <mesh filename="package://robot_4r_description/meshes/link_1.stl" scale="0.001 0.001 0.001" />
            </geometry>
        </collision>
    </link>
    <link name="link_2">
        <inertial>
            <origin xyz="0.05004615068431125 0.0 -0.013679619640488347" rpy="0.0 -0.0 0.0" />
            <mass value="0.1423760146884144" />
            <inertia ixx="2.879776704405837e-05" iyy="0.00018022540540958525" izz="0.00018731075720864517" ixy="0.0" iyz="1.3505996321327985e-20" ixz="5.8704830277803675e-06" />
        </inertial>
        <visual name="link_2_visual">
            <origin xyz="-0.12 0.0 0.07" rpy="3.141592653589793 -0.0 0.0" />
            <geometry>
                <mesh filename="package://robot_4r_description/meshes/link_2.stl" scale="0.001 0.001 0.001" />
            </geometry>
        </visual>
        <collision name="link_2_collision">
            <origin xyz="-0.12 0.0 0.07" rpy="3.141592653589793 -0.0 0.0" />
            <geometry>
                <mesh filename="package://robot_4r_description/meshes/link_2.stl" scale="0.001 0.001 0.001" />
            </geometry>
        </collision>
    </link>
    <link name="link_3">
        <inertial>
            <origin xyz="0.038549302577276415 -3.058116653443173e-18 -0.015" rpy="0.0 -0.0 0.0" />
            <mass value="0.11041106219837468" />
            <inertia ixx="1.953993134944554e-05" iyy="9.10065862260584e-05" izz="9.398485824574972e-05" ixy="2.5813570953856588e-20" iyz="-3.376499080331997e-20" ixz="0.0" />
        </inertial>
        <visual name="link_3_visual">
            <origin xyz="-0.20500000000000002 0.0 0.095" rpy="3.141592653589793 -0.0 0.0" />
            <geometry>
                <mesh filename="package://robot_4r_description/meshes/link_3.stl" scale="0.001 0.001 0.001" />
            </geometry>
        </visual>
        <collision name="link_3_collision">
            <origin xyz="-0.20500000000000002 0.0 0.095" rpy="3.141592653589793 -0.0 0.0" />
            <geometry>
                <mesh filename="package://robot_4r_description/meshes/link_3.stl" scale="0.001 0.001 0.001" />
            </geometry>
        </collision>
    </link>

    <joint name="base_link_Revolución-1" type="continuous">
        <origin xyz="0.0 0.0 0.04" rpy="0.0 -0.0 0.0" />
        <parent link="base_link" />
        <child link="link_1" />
        <axis xyz="0.0 0.0 1.0" />
    </joint>
    <joint name="link_1_Revolución-2" type="continuous">
        <origin xyz="0.12 0.0 0.03" rpy="3.141592653589793 -0.0 0.0" />
        <parent link="link_1" />
        <child link="link_2" />
        <axis xyz="0.0 0.0 1.0" />
    </joint>
    <joint name="link_2_Revolución-3" type="continuous">
        <origin xyz="0.085 0.0 -0.025" rpy="0.0 -0.0 0.0" />
        <parent link="link_2" />
        <child link="link_3" />
        <axis xyz="0.0 0.0 1.0" />
    </joint>
</robot>

